<?xml version="1.0" encoding="UTF-8"?>
<mujoco model="smplx_neutral_skeleton">
  <compiler angle="radian" coordinate="local"/>
  <option timestep="0.002" gravity="0 0 -9.81"/>
  <default>
    <joint damping="1.0" armature="0.01" limited="true"/>
    <geom contype="1" conaffinity="1"/>
  </default>
  <worldbody>
    <body name="pelvis" pos="0 0 1">
      <freejoint name="root_free"/>
      <geom name="pelvis_joint" type="box" size="0.001 0.001 0.001" rgba="0.12 0.70 0.95 0"/>
      <geom name="pelvis_volume" type="ellipsoid" size="0.14 0.07 0.09" pos="0 -0.04 0" rgba="0.85 0.75 0.65 1"/>
      <geom name="bone_pelvis_l_hip" type="capsule" fromto="0.0 0.0 0.0 0.05301883682142309 -0.08452089501565022 -0.02369077963522009" size="0.05" rgba="0.95 0.65 0.30 1"/>
      <body name="l_hip" pos="0.058189 -0.092763 -0.026001">
        <joint name="l_hip_ball" type="ball"range="0 1.57"/>
        <geom name="l_hip_joint" type="box" size="0.001 0.001 0.001" rgba="0.12 0.70 0.95 0"/>
        <geom name="bone_l_hip_l_knee" type="capsule" fromto="0.0071441230823986214 -0.049471762497992955 -0.0012272818444504514 0.046122052301121652 -0.31938688500240847 -0.0079232617866594589" size="0.06" rgba="0.95 0.65 0.30 1"/>
        <body name="l_knee" pos="0.054695 -0.378753 -0.009396">
          <joint name="l_knee_ball" type="ball"range="0 2.36"/>
          <geom name="l_knee_joint" type="box" size="0.001 0.001 0.001" rgba="0.12 0.70 0.95 0"/>
          <geom name="bone_l_knee_l_ankle" type="capsule" fromto="-0.0053428432006085817 -0.049558980517738591 -0.0039193719619496732 -0.037041588159269695 -0.34358922337871367 -0.027172753645660394" size="0.05" rgba="0.95 0.65 0.30 1"/>
          <body name="l_ankle" pos="-0.043453 -0.403060 -0.031876">
            <joint name="l_ankle_ball" type="ball"range="0 0.70"/>
            <geom name="l_ankle_joint" type="box" size="0.001 0.001 0.001" rgba="0.12 0.70 0.95 0"/>
            <geom name="bone_l_ankle_l_foot" type="capsule" fromto="0.016889611991308808 -0.020728078944070447 0.042250298816356571 0.02698946561042943 -0.03312330526711546 0.067515641420372113" size="0.04" rgba="0.95 0.65 0.30 1"/>
            <body name="l_foot" pos="0.047257 -0.057997 0.118216">
              <joint name="l_foot_ball" type="ball"range="0 0.52"/>
              <geom name="l_foot_joint" type="box" size="0.001 0.001 0.001" rgba="0.12 0.70 0.95 0"/>
              <geom name="l_foot_volume" type="box" size="0.04 0.02 0.10" pos="0 -0.02 0.04" rgba="0.85 0.75 0.65 1"/>
            </body>
          </body>
        </body>
      </body>
      <geom name="bone_pelvis_r_hip" type="capsule" fromto="0.0 0.0 0.0 -0.05814398095779991 -0.0954940928661557 -0.019529290077817" size="0.05" rgba="0.95 0.65 0.30 1"/>
      <body name="r_hip" pos="-0.063267 -0.103908 -0.021250">
        <joint name="r_hip_ball" type="ball"range="0 1.57"/>
        <geom name="r_hip_joint" type="box" size="0.001 0.001 0.001" rgba="0.12 0.70 0.95 0"/>
        <geom name="bone_r_hip_r_knee" type="capsule" fromto="-0.0060486361277753212 -0.049579388373291566 -0.0023017926761748921 -0.036951636646669617 -0.30288473395205007 -0.014061848788590127" size="0.06" rgba="0.95 0.65 0.30 1"/>
        <body name="r_knee" pos="-0.044210 -0.362380 -0.016824">
          <joint name="r_knee_ball" type="ball"range="0 2.36"/>
          <geom name="r_knee_joint" type="box" size="0.001 0.001 0.001" rgba="0.12 0.70 0.95 0"/>
          <geom name="bone_r_knee_r_ankle" type="capsule" fromto="0.0018732096750076451 -0.049904628876989043 -0.0024533858570249967 0.013169148389990826 -0.35084244534761311 -0.017247936971570003" size="0.05" rgba="0.95 0.65 0.30 1"/>
          <body name="r_ankle" pos="0.015417 -0.410728 -0.020192">
            <joint name="r_ankle_ball" type="ball"range="0 0.70"/>
            <geom name="r_ankle_joint" type="box" size="0.001 0.001 0.001" rgba="0.12 0.70 0.95 0"/>
            <geom name="bone_r_ankle_r_foot" type="capsule" fromto="-0.014048564712986584 -0.021113025124801465 0.043091507279097697 -0.021953722344416095 -0.032993369850238236 0.067339191265082754" size="0.04" rgba="0.95 0.65 0.30 1"/>
            <body name="r_foot" pos="-0.038812 -0.058329 0.119049">
              <joint name="r_foot_ball" type="ball"range="0 0.52"/>
              <geom name="r_foot_joint" type="box" size="0.001 0.001 0.001" rgba="0.12 0.70 0.95 0"/>
              <geom name="r_foot_volume" type="box" size="0.04 0.02 0.10" pos="0 -0.02 0.04" rgba="0.85 0.75 0.65 1"/>
            </body>
          </body>
        </body>
      </body>
      <geom name="bone_pelvis_spine1" type="capsule" fromto="-0.0010767807855883327 0.042826101089065309 -0.010763131283524636 -0.0014424438428823334 0.057369379782186945 -0.014418173743295074" size="0.06" rgba="0.95 0.65 0.30 1"/>
      <body name="spine1" pos="-0.002763 0.109891 -0.027618">
        <joint name="spine1_ball" type="ball"range="0 0.35"/>
        <geom name="spine1_joint" type="box" size="0.001 0.001 0.001" rgba="0.12 0.70 0.95 0"/>
        <geom name="abdomen_volume" type="ellipsoid" size="0.12 0.06 0.09" pos="0 0.05 0" rgba="0.85 0.75 0.65 1"/>
        <geom name="bone_spine1_spine2" type="capsule" fromto="0.0035700127611260797 0.049821855693560228 -0.0022444830441457359 0.0051639846866487048 0.072066773167727721 -0.0032466203470251165" size="0.06" rgba="0.95 0.65 0.30 1"/>
        <body name="spine2" pos="0.009448 0.131853 -0.005940">
          <joint name="spine2_ball" type="ball"range="0 0.35"/>
          <geom name="spine2_joint" type="box" size="0.001 0.001 0.001" rgba="0.12 0.70 0.95 0"/>
          <geom name="chest_ellipsoid" type="ellipsoid" size="0.14 0.07 0.10" pos="0 0.06 0.01" rgba="0.85 0.75 0.65 1"/>
          <geom name="bone_spine2_spine3" type="capsule" fromto="-0.0033259580533324014 0.015333752772799469 0.008350708626932643 -0.0061328083893335186 0.028274249445440103 0.01539805827461347" size="0.05" rgba="0.95 0.65 0.30 1"/>
          <body name="spine3" pos="-0.011330 0.052235 0.028447">
            <joint name="spine3_ball" type="ball"range="0 0.35"/>
            <geom name="spine3_joint" type="box" size="0.001 0.001 0.001" rgba="0.12 0.70 0.95 0"/>
            <geom name="upper_chest_volume" type="ellipsoid" size="0.13 0.05 0.09" pos="0 0.08 0" rgba="0.85 0.75 0.65 1"/>
            <geom name="bone_spine3_neck" type="capsule" fromto="-0.0036072500576031135 0.048980489170020847 -0.0093754694649064805 -0.0078352999308762619 0.10639041299597499 -0.020364436642112217" size="0.04" rgba="0.95 0.65 0.30 1"/>
            <body name="neck" pos="-0.012164 0.165167 -0.031615">
              <joint name="neck_ball" type="ball"range="0 0.52"/>
              <geom name="neck_joint" type="box" size="0.001 0.001 0.001" rgba="0.12 0.70 0.95 0"/>
              <geom name="bone_neck_head" type="capsule" fromto="0.0087133562434793897 0.048828809122398641 0.0063106911398498021 0.018169481597099607 0.101820024794882 0.013159336463063519" size="0.04" rgba="0.95 0.65 0.30 1"/>
              <body name="head" pos="0.024783 0.160452 0.020737">
                <joint name="head_ball" type="ball"range="0 0.52"/>
                <geom name="head_joint" type="sphere" size="0.10" rgba="0.85 0.75 0.65 1"/>
                <geom name="bone_head_jaw" type="capsule" fromto="0.0 0.0 0.0 -0.0063537548123213175 -0.0002095751666607729 -0.00227268147076942" size="0.008" rgba="0.95 0.65 0.30 1"/>
                <body name="jaw" pos="-0.015765 -0.000520 -0.005639">
                  <joint name="jaw_ball" type="ball"range="0 0.17"/>
                  <geom name="jaw_joint" type="box" size="0.001 0.001 0.001" rgba="0.12 0.70 0.95 0"/>
                </body>
                <geom name="bone_head_l_eye" type="capsule" fromto="0.0 0.0 0.0 0.017981069203615956 0.03739872953763494 0.058013549146989786" size="0.008" rgba="0.95 0.65 0.30 1"/>
                <body name="l_eye" pos="0.020502 0.042642 0.066147">
                  <joint name="l_eye_ball" type="ball"range="0 0.17"/>
                  <geom name="l_eye_joint" type="box" size="0.001 0.001 0.001" rgba="0.12 0.70 0.95 0"/>
                </body>
                <geom name="bone_head_r_eye" type="capsule" fromto="0.0 0.0 0.0 -0.03792833462645577 0.03787947736705921 0.058759293405535984" size="0.008" rgba="0.95 0.65 0.30 1"/>
                <body name="r_eye" pos="-0.042697 0.042642 0.066147">
                  <joint name="r_eye_ball" type="ball"range="0 0.17"/>
                  <geom name="r_eye_joint" type="box" size="0.001 0.001 0.001" rgba="0.12 0.70 0.95 0"/>
                </body>
              </body>
            </body>
            <geom name="bone_spine3_l_collar" type="capsule" fromto="0.0 0.0 0.0 0.04158629576019484 0.07619071493085132 -0.006475995500573866" size="0.04" rgba="0.95 0.65 0.30 1"/>
            <body name="l_collar" pos="0.046364 0.084944 -0.007220">
              <joint name="l_collar_ball" type="ball"range="0 0.26"/>
              <geom name="l_collar_joint" type="box" size="0.001 0.001 0.001" rgba="0.12 0.70 0.95 0"/>
              <geom name="bone_l_collar_l_shoulder" type="capsule" fromto="0.039335899572488217 0.019043960537413095 -0.0051004482031067047 0.070963123251946258 0.034355866613174843 -0.0092013590234599554" size="0.05" rgba="0.95 0.65 0.30 1"/>
              <body name="l_shoulder" pos="0.119239 0.057728 -0.015461">
                <joint name="l_shoulder_ball" type="ball"range="0 2.09"/>
                <geom name="l_shoulder_joint" type="box" size="0.001 0.001 0.001" rgba="0.12 0.70 0.95 0"/>
                <geom name="bone_l_shoulder_l_elbow" type="capsule" fromto="0.04179068307786394 -0.011865276164498929 -0.0069824085690906573 0.20283443440443971 -0.05758907016175132 -0.033889680392479644" size="0.04" rgba="0.95 0.65 0.30 1"/>
                <body name="l_elbow" pos="0.254123 -0.072151 -0.042459">
                  <joint name="l_elbow_ball" type="ball"range="0 2.36"/>
                  <geom name="l_elbow_joint" type="box" size="0.001 0.001 0.001" rgba="0.12 0.70 0.95 0"/>
                  <geom name="bone_l_elbow_l_wrist" type="capsule" fromto="0.043812269029263384 0.0040373697814908103 -0.00042979966839693732 0.1982173971004495 0.018266046177261276 -0.0019445185887855764" size="0.035" rgba="0.95 0.65 0.30 1"/>
                  <body name="l_wrist" pos="0.251987 0.023221 -0.002472">
                    <joint name="l_wrist_ball" type="ball"range="0 1.22"/>
                    <geom name="l_wrist_joint" type="box" size="0.001 0.001 0.001" rgba="0.12 0.70 0.95 0"/>
                    <geom name="l_palm" type="box" size="0.035 0.01 0.045" pos="0.04 0 0" rgba="0.85 0.75 0.65 1"/>
                    <geom name="bone_l_wrist_l_index1" type="capsule" fromto="0.024475360632757445 -0.0020867297322662627 0.0046478253969940665 0.067636495114139578 -0.0057665783748272331 0.012844044444208308" size="0.012" rgba="0.95 0.65 0.30 1"/>
                    <body name="l_index1" pos="0.101902 -0.008688 0.019351">
                      <joint name="l_index1_ball" type="ball"range="0 1.22"/>
                      <geom name="l_index1_joint" type="box" size="0.001 0.001 0.001" rgba="0.12 0.70 0.95 0"/>
                      <geom name="bone_l_index1_l_index2" type="capsule" fromto="0.0 0.0 0.0 0.022015786730355404 0.0015284529537976802 0.00207423056399054" size="0.008" rgba="0.95 0.65 0.30 1"/>
                      <body name="l_index2" pos="0.031948 0.002218 0.003010">
                        <joint name="l_index2_ball" type="ball"range="0 1.22"/>
                        <geom name="l_index2_joint" type="box" size="0.001 0.001 0.001" rgba="0.12 0.70 0.95 0"/>
                        <geom name="bone_l_index2_l_index3" type="capsule" fromto="0.0 0.0 0.0 0.01259891624704195 -0.0013132602874494825 3.0735879067966616e-05" size="0.008" rgba="0.95 0.65 0.30 1"/>
                        <body name="l_index3" pos="0.022545 -0.002350 0.000055">
                          <joint name="l_index3_ball" type="ball"range="0 1.22"/>
                          <geom name="l_index3_joint" type="box" size="0.001 0.001 0.001" rgba="0.12 0.70 0.95 0"/>
                        </body>
                      </body>
                    </body>
                    <geom name="bone_l_wrist_l_middle1" type="capsule" fromto="0.024941826853642518 -0.0014427309487362646 -0.00090763462498721068 0.074479442404900467 -0.00430817667176923 -0.002710311525017905" size="0.012" rgba="0.95 0.65 0.30 1"/>
                    <body name="l_middle1" pos="0.109398 -0.006328 -0.003981">
                      <joint name="l_middle1_ball" type="ball"range="0 1.22"/>
                      <geom name="l_middle1_joint" type="box" size="0.001 0.001 0.001" rgba="0.12 0.70 0.95 0"/>
                      <geom name="bone_l_middle1_l_middle2" type="capsule" fromto="0.0 0.0 0.0 0.020699642816656136 0.0005457061759838457 -0.0027204162899417735" size="0.008" rgba="0.95 0.65 0.30 1"/>
                      <body name="l_middle2" pos="0.030611 0.000807 -0.004023">
                        <joint name="l_middle2_ball" type="ball"range="0 1.22"/>
                        <geom name="l_middle2_joint" type="box" size="0.001 0.001 0.001" rgba="0.12 0.70 0.95 0"/>
                        <geom name="bone_l_middle2_l_middle3" type="capsule" fromto="0.0 0.0 0.0 0.013699312970276416 -0.0011703984587406045 -0.002396724369964583" size="0.008" rgba="0.95 0.65 0.30 1"/>
                        <body name="l_middle3" pos="0.023515 -0.002009 -0.004114">
                          <joint name="l_middle3_ball" type="ball"range="0 1.22"/>
                          <geom name="l_middle3_joint" type="box" size="0.001 0.001 0.001" rgba="0.12 0.70 0.95 0"/>
                        </body>
                      </body>
                    </body>
                    <geom name="bone_l_wrist_l_pinky1" type="capsule" fromto="0.021918962231591704 -0.0037916855079314169 -0.011409742139899544 0.053360452875771611 -0.0092306402888960165 -0.027776361004140639" size="0.012" rgba="0.95 0.65 0.30 1"/>
                    <body name="l_pinky1" pos="0.084047 -0.014539 -0.043750">
                      <joint name="l_pinky1_ball" type="ball"range="0 1.22"/>
                      <geom name="l_pinky1_joint" type="box" size="0.001 0.001 0.001" rgba="0.12 0.70 0.95 0"/>
                      <geom name="bone_l_pinky1_l_pinky2" type="capsule" fromto="0.0 0.0 0.0 0.007582244161529352 -0.0005547863997706177 -0.005880637818770001" size="0.008" rgba="0.95 0.65 0.30 1"/>
                      <body name="l_pinky2" pos="0.015471 -0.001132 -0.011999">
                        <joint name="l_pinky2_ball" type="ball"range="0 1.22"/>
                        <geom name="l_pinky2_joint" type="box" size="0.001 0.001 0.001" rgba="0.12 0.70 0.95 0"/>
                        <geom name="bone_l_pinky2_l_pinky3" type="capsule" fromto="0.0 0.0 0.0 0.007456330472008274 -0.0007992525742544117 -0.005384514189436478" size="0.008" rgba="0.95 0.65 0.30 1"/>
                        <body name="l_pinky3" pos="0.015533 -0.001665 -0.011217">
                          <joint name="l_pinky3_ball" type="ball"range="0 1.22"/>
                          <geom name="l_pinky3_joint" type="box" size="0.001 0.001 0.001" rgba="0.12 0.70 0.95 0"/>
                        </body>
                      </body>
                    </body>
                    <geom name="bone_l_wrist_l_ring1" type="capsule" fromto="0.023969911793695304 -0.0022798031946961133 -0.0067265017651019889 0.063886123488826579 -0.0060762755274254409 -0.01792789752885722" size="0.012" rgba="0.95 0.65 0.30 1"/>
                    <body name="l_ring1" pos="0.097444 -0.009268 -0.027345">
                      <joint name="l_ring1_ball" type="ball"range="0 1.22"/>
                      <geom name="l_ring1_joint" type="box" size="0.001 0.001 0.001" rgba="0.12 0.70 0.95 0"/>
                      <geom name="bone_l_ring1_l_ring2" type="capsule" fromto="0.0 0.0 0.0 0.01823201469261466 0.0009653275508443959 -0.0034231750052165577" size="0.008" rgba="0.95 0.65 0.30 1"/>
                      <body name="l_ring2" pos="0.028047 0.001485 -0.005266">
                        <joint name="l_ring2_ball" type="ball"range="0 1.22"/>
                        <geom name="l_ring2_joint" type="box" size="0.001 0.001 0.001" rgba="0.12 0.70 0.95 0"/>
                        <geom name="bone_l_ring2_l_ring3" type="capsule" fromto="0.0 0.0 0.0 0.013290420046813118 -0.0008490681109566878 -0.004131199711335214" size="0.008" rgba="0.95 0.65 0.30 1"/>
                        <body name="l_ring3" pos="0.022822 -0.001458 -0.007094">
                          <joint name="l_ring3_ball" type="ball"range="0 1.22"/>
                          <geom name="l_ring3_joint" type="box" size="0.001 0.001 0.001" rgba="0.12 0.70 0.95 0"/>
                        </body>
                      </body>
                    </body>
                    <geom name="bone_l_wrist_l_thumb1" type="capsule" fromto="0.019808048234757996 -0.0087629019371061254 0.012484100879525225 0.0129047324713388 -0.0057089372880514237 0.0081332587686646814" size="0.012" rgba="0.95 0.65 0.30 1"/>
                    <body name="l_thumb1" pos="0.040636 -0.017977 0.025611">
                      <joint name="l_thumb1_ball" type="ball"range="0 1.22"/>
                      <geom name="l_thumb1_joint" type="box" size="0.001 0.001 0.001" rgba="0.12 0.70 0.95 0"/>
                      <geom name="bone_l_thumb1_l_thumb2" type="capsule" fromto="0.0 0.0 0.0 0.011388830389356626 0.0006532380383175874 0.0167178070912876" size="0.008" rgba="0.95 0.65 0.30 1"/>
                      <body name="l_thumb2" pos="0.017016 0.000976 0.024978">
                        <joint name="l_thumb2_ball" type="ball"range="0 1.22"/>
                        <geom name="l_thumb2_joint" type="box" size="0.001 0.001 0.001" rgba="0.12 0.70 0.95 0"/>
                        <geom name="bone_l_thumb2_l_thumb3" type="capsule" fromto="0.0 0.0 0.0 0.012703126221246891 -0.0031938864348113804 0.009608275024724236" size="0.008" rgba="0.95 0.65 0.30 1"/>
                        <body name="l_thumb3" pos="0.020523 -0.005160 0.015523">
                          <joint name="l_thumb3_ball" type="ball"range="0 1.22"/>
                          <geom name="l_thumb3_joint" type="box" size="0.001 0.001 0.001" rgba="0.12 0.70 0.95 0"/>
                        </body>
                      </body>
                    </body>
                  </body>
                </body>
              </body>
            </body>
            <geom name="bone_spine3_r_collar" type="capsule" fromto="0.0 0.0 0.0 -0.042818873311245974 0.07571655217941449 -0.012030043031149934" size="0.04" rgba="0.95 0.65 0.30 1"/>
            <body name="r_collar" pos="-0.047695 0.084339 -0.013400">
              <joint name="r_collar_ball" type="ball"range="0 0.26"/>
              <geom name="r_collar_joint" type="box" size="0.001 0.001 0.001" rgba="0.12 0.70 0.95 0"/>
              <geom name="bone_r_collar_r_shoulder" type="capsule" fromto="-0.038777180693270921 0.020233479102991218 -0.0047892150578393916 -0.054987823694622059 0.028692002919056235 -0.0067913269744698376" size="0.05" rgba="0.95 0.65 0.30 1"/>
              <body name="r_shoulder" pos="-0.102578 0.053524 -0.012669">
                <joint name="r_shoulder_ball" type="ball"range="0 2.09"/>
                <geom name="r_shoulder_joint" type="box" size="0.001 0.001 0.001" rgba="0.12 0.70 0.95 0"/>
                <geom name="bone_r_shoulder_r_elbow" type="capsule" fromto="-0.043404238798104428 -0.005841443784696392 -0.0042366955127030419 -0.21788116147505363 -0.029322955355145338 -0.021267419143500811" size="0.04" rgba="0.95 0.65 0.30 1"/>
                <body name="r_elbow" pos="-0.271150 -0.036492 -0.026467">
                  <joint name="r_elbow_ball" type="ball"range="0 2.36"/>
                  <geom name="r_elbow_joint" type="box" size="0.001 0.001 0.001" rgba="0.12 0.70 0.95 0"/>
                  <geom name="bone_r_elbow_r_wrist" type="capsule" fromto="-0.043909846218790377 -0.00079851457637704457 -0.0026995887674780964 -0.19537764327693904 -0.0035530048380827172 -0.012011868330822335" size="0.035" rgba="0.95 0.65 0.30 1"/>
                  <body name="r_wrist" pos="-0.249267 -0.004533 -0.015325">
                    <joint name="r_wrist_ball" type="ball"range="0 1.22"/>
                    <geom name="r_wrist_joint" type="box" size="0.001 0.001 0.001" rgba="0.12 0.70 0.95 0"/>
                    <geom name="r_palm" type="box" size="0.035 0.01 0.045" pos="-0.04 0 0" rgba="0.85 0.75 0.65 1"/>
                    <geom name="bone_r_wrist_r_index1" type="capsule" fromto="-0.024369381795128101 -0.0028748653466824973 0.004782089518371971 -0.065763865486820658 -0.007758188514644505 0.012905074674279243" size="0.012" rgba="0.95 0.65 0.30 1"/>
                    <body name="r_index1" pos="-0.099881 -0.011783 0.019600">
                      <joint name="r_index1_ball" type="ball"range="0 1.22"/>
                      <geom name="r_index1_joint" type="box" size="0.001 0.001 0.001" rgba="0.12 0.70 0.95 0"/>
                      <geom name="bone_r_index1_r_index2" type="capsule" fromto="0.0 0.0 0.0 -0.022015815629666733 0.0015284549601415054 0.0020749224008052626" size="0.008" rgba="0.95 0.65 0.30 1"/>
                      <body name="r_index2" pos="-0.031948 0.002218 0.003011">
                        <joint name="r_index2_ball" type="ball"range="0 1.22"/>
                        <geom name="r_index2_joint" type="box" size="0.001 0.001 0.001" rgba="0.12 0.70 0.95 0"/>
                        <geom name="bone_r_index2_r_index3" type="capsule" fromto="0.0 0.0 0.0 -0.012598870765593745 -0.001312696714498989 3.073576811300315e-05" size="0.008" rgba="0.95 0.65 0.30 1"/>
                        <body name="r_index3" pos="-0.022545 -0.002349 0.000055">
                          <joint name="r_index3_ball" type="ball"range="0 1.22"/>
                          <geom name="r_index3_joint" type="box" size="0.001 0.001 0.001" rgba="0.12 0.70 0.95 0"/>
                        </body>
                      </body>
                    </body>
                    <geom name="bone_r_wrist_r_middle1" type="capsule" fromto="-0.024889376558038124 -0.0021839862346319026 -0.00086552797708719224 -0.072530872818746636 -0.0063644192715153359 -0.002522260832077931" size="0.012" rgba="0.95 0.65 0.30 1"/>
                    <body name="r_middle1" pos="-0.107376 -0.009422 -0.003734">
                      <joint name="r_middle1_ball" type="ball"range="0 1.22"/>
                      <geom name="r_middle1_joint" type="box" size="0.001 0.001 0.001" rgba="0.12 0.70 0.95 0"/>
                      <geom name="bone_r_middle1_r_middle2" type="capsule" fromto="0.0 0.0 0.0 -0.020699642816656136 0.0005457061759838457 -0.0027204162899417735" size="0.008" rgba="0.95 0.65 0.30 1"/>
                      <body name="r_middle2" pos="-0.030611 0.000807 -0.004023">
                        <joint name="r_middle2_ball" type="ball"range="0 1.22"/>
                        <geom name="r_middle2_joint" type="box" size="0.001 0.001 0.001" rgba="0.12 0.70 0.95 0"/>
                        <geom name="bone_r_middle2_r_middle3" type="capsule" fromto="0.0 0.0 0.0 -0.01370029772574565 -0.0011704328172743243 -0.0023967947288534444" size="0.008" rgba="0.95 0.65 0.30 1"/>
                        <body name="r_middle3" pos="-0.023516 -0.002009 -0.004114">
                          <joint name="r_middle3_ball" type="ball"range="0 1.22"/>
                          <geom name="r_middle3_joint" type="box" size="0.001 0.001 0.001" rgba="0.12 0.70 0.95 0"/>
                        </body>
                      </body>
                    </body>
                    <geom name="bone_r_wrist_r_pinky1" type="capsule" fromto="-0.021698262901451985 -0.004664649054630844 -0.011507668584757038 -0.051649431937967234 -0.011103491323516818 -0.027392263981340148" size="0.012" rgba="0.95 0.65 0.30 1"/>
                    <body name="r_pinky1" pos="-0.082027 -0.017634 -0.043503">
                      <joint name="r_pinky1_ball" type="ball"range="0 1.22"/>
                      <geom name="r_pinky1_joint" type="box" size="0.001 0.001 0.001" rgba="0.12 0.70 0.95 0"/>
                      <geom name="bone_r_pinky1_r_pinky2" type="capsule" fromto="0.0 0.0 0.0 -0.007582244161529352 -0.0005547863997706177 -0.005880637818770001" size="0.008" rgba="0.95 0.65 0.30 1"/>
                      <body name="r_pinky2" pos="-0.015471 -0.001132 -0.011999">
                        <joint name="r_pinky2_ball" type="ball"range="0 1.22"/>
                        <geom name="r_pinky2_joint" type="box" size="0.001 0.001 0.001" rgba="0.12 0.70 0.95 0"/>
                        <geom name="bone_r_pinky2_r_pinky3" type="capsule" fromto="0.0 0.0 0.0 -0.007456085529944888 -0.0007992263186350504 -0.005383857291177613" size="0.008" rgba="0.95 0.65 0.30 1"/>
                        <body name="r_pinky3" pos="-0.015533 -0.001665 -0.011216">
                          <joint name="r_pinky3_ball" type="ball"range="0 1.22"/>
                          <geom name="r_pinky3_joint" type="box" size="0.001 0.001 0.001" rgba="0.12 0.70 0.95 0"/>
                        </body>
                      </body>
                    </body>
                    <geom name="bone_r_wrist_r_ring1" type="capsule" fromto="-0.023864433730566383 -0.0030916249727766013 -0.0067772160764660349 -0.062012792777207067 -0.008033725038112758 -0.017610897492947555" size="0.012" rgba="0.95 0.65 0.30 1"/>
                    <body name="r_ring1" pos="-0.095423 -0.012362 -0.027099">
                      <joint name="r_ring1_ball" type="ball"range="0 1.22"/>
                      <geom name="r_ring1_joint" type="box" size="0.001 0.001 0.001" rgba="0.12 0.70 0.95 0"/>
                      <geom name="bone_r_ring1_r_ring2" type="capsule" fromto="0.0 0.0 0.0 -0.01823201469261466 0.0009653275508443959 -0.0034231750052165577" size="0.008" rgba="0.95 0.65 0.30 1"/>
                      <body name="r_ring2" pos="-0.028047 0.001485 -0.005266">
                        <joint name="r_ring2_ball" type="ball"range="0 1.22"/>
                        <geom name="r_ring2_joint" type="box" size="0.001 0.001 0.001" rgba="0.12 0.70 0.95 0"/>
                        <geom name="bone_r_ring2_r_ring3" type="capsule" fromto="0.0 0.0 0.0 -0.013290326358028072 -0.0008496444727176829 -0.004130588241937303" size="0.008" rgba="0.95 0.65 0.30 1"/>
                        <body name="r_ring3" pos="-0.022822 -0.001459 -0.007093">
                          <joint name="r_ring3_ball" type="ball"range="0 1.22"/>
                          <geom name="r_ring3_joint" type="box" size="0.001 0.001 0.001" rgba="0.12 0.70 0.95 0"/>
                        </body>
                      </body>
                    </body>
                    <geom name="bone_r_wrist_r_thumb1" type="capsule" fromto="-0.018917512268624564 -0.010324700322404215 0.012669976038611343 -0.012128482823925611 -0.0066194195486340961 0.008123033545944118" size="0.012" rgba="0.95 0.65 0.30 1"/>
                    <body name="r_thumb1" pos="-0.038613 -0.021074 0.025861">
                      <joint name="r_thumb1_ball" type="ball"range="0 1.22"/>
                      <geom name="r_thumb1_joint" type="box" size="0.001 0.001 0.001" rgba="0.12 0.70 0.95 0"/>
                      <geom name="bone_r_thumb1_r_thumb2" type="capsule" fromto="0.0 0.0 0.0 -0.011388056378517558 0.0006532320320560175 0.01671765337776148" size="0.008" rgba="0.95 0.65 0.30 1"/>
                      <body name="r_thumb2" pos="-0.017015 0.000976 0.024978">
                        <joint name="r_thumb2_ball" type="ball"range="0 1.22"/>
                        <geom name="r_thumb2_joint" type="box" size="0.001 0.001 0.001" rgba="0.12 0.70 0.95 0"/>
                        <geom name="bone_r_thumb2_r_thumb3" type="capsule" fromto="0.0 0.0 0.0 -0.012704478269810377 -0.0031920581942709923 0.009607742348550385" size="0.008" rgba="0.95 0.65 0.30 1"/>
                        <body name="r_thumb3" pos="-0.020525 -0.005157 0.015522">
                          <joint name="r_thumb3_ball" type="ball"range="0 1.22"/>
                          <geom name="r_thumb3_joint" type="box" size="0.001 0.001 0.001" rgba="0.12 0.70 0.95 0"/>
                        </body>
                      </body>
                    </body>
                  </body>
                </body>
              </body>
            </body>
          </body>
        </body>
      </body>
    </body>
  </worldbody>
</mujoco>
